Workbook

Sheet 01 README
A1: Investment Analysis Toolkit — Excel Edition
A2: A formula-for-formula translation of the investment_analysis Python package. No VBA, no macros: every number is a native Excel formula you can click into and audit.
A3: Mirrors: Project 1 — Investment Analysis (Markowitz Frontier)
A5: HOW TO USE THIS WORKBOOK
A6: 1. Open in Microsoft 365 Excel | B6: Sheet '03 Raw Data' pulls live prices with STOCKHISTORY(), which needs a Microsoft 365 subscription and an internet connection. In Excel for the web, LibreOffice or a perpetual-licence version (2019/2021) those cells return a name error and nothing downstream will compute.
A7: 2. Let it calculate | B7: On first open Excel fetches ~700 days x 7 tickers. Give it a few seconds. If the sheets look empty, press Ctrl+Alt+F9 to force a full recalculation.
A8: 3. Set the risk-free rate | B8: Cell B10 on '02 Config' is the one market number that cannot be fetched by formula — STOCKHISTORY does not cover Treasury yield tickers. Enter the current 5-year Treasury yield as a decimal. The Python project pulls this automatically from ^FVX.
A9: 4. Change anything blue | B9: Tickers, dates, portfolio value, confidence levels — every blue cell is an input, and the entire workbook re-solves from it. Nothing is hardcoded downstream.
A12: SHEET MAP — WHICH PYTHON MODULE EACH SHEET REPLACES
A13: Sheet | B13: What it does | C13: Python source
A14: 02 Config | B14: All inputs: dates, tickers, risk-free rate, portfolio value, VaR confidence levels, simulation settings. | C14: config.py (AnalysisConfig) + portfolio.xlsx
A15: 03 Raw Data | B15: Live STOCKHISTORY price feed, one block per asset plus the benchmark. The only cells touching the internet. | C15: data.py — download_prices(), download_benchmark()
A16: 04 Prices | B16: Raw blocks stitched onto one shared trading calendar with INDEX/MATCH. | C16: the aligned DataFrame yfinance returns
A17: 05 Simple Returns | B17: Daily simple returns, P_t/P_(t-1) - 1. | C17: returns.py — simple_returns()
A18: 06 Log Returns | B18: Daily log returns, ln(P_t/P_(t-1)). | C18: returns.py — log_returns()
A19: 07 Annualised Inputs | B19: Annualised expected returns, the annualised covariance matrix, and the correlation matrix. | C19: optimization.py — annualized_inputs()
A20: 08 Optimisation | B20: Matrix-algebra solution: Sigma inverse, the frontier constants A/B/C/D, minimum-variance and tangency weights, the 100-point frontier. | C20: optimization.py — PortfolioMath, minimum_volatility_portfolio(), maximum_sharpe_portfolio(), efficient_frontier()
A21: 09 Monte Carlo | B21: 1,000 randomly weighted portfolios forming the feasible-set cloud. | C21: optimization.py — monte_carlo_portfolios()
A22: 10 Portfolio Returns | B22: Asset returns collapsed to one portfolio series, plus cumulative growth and the drawdown path. | C22: returns.py — portfolio_returns(); risk_metrics.py — max_drawdown()
A23: 11 Risk Metrics | B23: Beta, Alpha, Sharpe, Sortino, Calmar, Treynor, max drawdown, VaR and CVaR. | C23: risk_metrics.py (all functions)
A24: 12 Charts | B24: Price lines, the efficient frontier scatter, growth of $1 and the drawdown chart. | C24: visualization.py — plot_prices(), plot_efficient_frontier()
A27: THREE PLACES THIS WORKBOOK KNOWINGLY DIFFERS FROM THE PYTHON PROJECT
A28: Unconstrained optimisation | B28: optimization.py bounds every weight to [0, 1] and solves numerically with SciPy's SLSQP. A bounded problem has no closed form, so the matrix solution on '08 Optimisation' solves the same objective WITHOUT the bounds. Where a short position would help, these weights differ and this frontier sits slightly to the left of the Python one — constraints can never reduce risk. Everything else in the workbook is identical maths.
A29: Unadjusted closing prices | B29: data.py requests 'Adj Close', which is back-adjusted for dividends and splits. STOCKHISTORY returns the unadjusted close. Total-return figures will therefore sit slightly below the Python output for dividend-paying holdings, and a split in the sample period would show as a jump.
A30: Risk-free rate is a manual input | B30: data.download_risk_free_rate() pulls ^FVX and divides by 100. STOCKHISTORY cannot address Treasury yield tickers, so cell B10 on '02 Config' is typed in by hand.
A31: 1,000 Monte Carlo draws instead of 10,000 | B31: Purely for file size and recalculation speed. The draws are the first rows of the same numpy default_rng(42) sequence, so they match the Python simulation row for row. The frontier itself is solved analytically and does not depend on the simulation at all.
A32: Sortino ratio kept 'wrong' on purpose | B32: risk_metrics.sortino_ratio() divides an annual excess return by a DAILY downside deviation, inflating the ratio by about SQRT(252). The workbook reproduces that rather than silently correcting it, and says so on '11 Risk Metrics'.
A35: COLOUR CONVENTION
A36: Blue text on cream fill | B36: Hardcoded input — safe to edit.
A37: Black text | B37: Calculated by formula — do not overwrite.
A38: Green text | B38: A link to another sheet.
A40: Cells with a small red corner carry a comment explaining the maths and naming the Python function they come from. Hover to read them.

Sheet 02 Config
A1: Configuration & Inputs
A2: Every analysis parameter lives here. Blue cells are hardcoded inputs you may edit; black cells are formulas. Nothing downstream hardcodes a parameter.
A3: Mirrors: config.py -> AnalysisConfig dataclass
A5: MARKET DATA & PORTFOLIO PARAMETERS
A6: Parameter | B6: Value | C6: Units | D6: What it does / where it comes from in the Python project
A7: Start date | B7: 45292 | C7: date | D7: config.py: start_date = dt.datetime(2024, 1, 1). First date requested from the market data feed.
A8: End date | B8: =TODAY() | C8: date | D8: config.py: end_date = None, which main.py resolves to dt.datetime.now(). TODAY() reproduces that behaviour live.
A9: Benchmark ticker | B9: SPX | C9: text | D9: config.py: benchmark_ticker = '^GSPC'. Excel's STOCKHISTORY addresses the S&P 500 as 'SPX'. Used for Beta, Alpha and Treynor. If your Excel build rejects 'SPX', try '.INX' or 'INDEX:SPX'.
A10: Risk-free rate (annual) | B10: 0.0375 | C10: % p.a. | D10: config.py: risk_free_ticker = '^FVX' (5-year Treasury yield), taken as latest close / 100. STOCKHISTORY cannot return Treasury yield tickers, so this is a MANUAL INPUT. Update it from the current 5-year Treasury yield, entered as a decimal (4.25% -> 0.0425).
A11: Portfolio value | B11: 1000000 | C11: $ | D11: config.py: portfolio_value = 1_000_000. Converts VaR and CVaR from a return into a currency loss.
A12: Trading days per year | B12: 252 | C12: days | D12: returns.py: TRADING_DAYS_PER_YEAR = 252. The annualisation factor used everywhere.
A13: VaR confidence level 1 | B13: 0.9 | C13: % | D13: config.py: var_confidence_levels = (0.90, 0.95, 0.99).
A14: VaR confidence level 2 | B14: 0.95 | C14: % | D14: config.py: var_confidence_levels[1].
A15: VaR confidence level 3 | B15: 0.99 | C15: % | D15: config.py: var_confidence_levels[2].
A16: Monte Carlo portfolios | B16: 1000 | C16: count | D16: config.py: n_monte_carlo_portfolios = 10_000. Reduced to 1,000 here to keep the workbook responsive; the random draws used are the FIRST 1,000 draws of numpy's default_rng(42), so these rows are numerically identical to the first rows of the Python simulation.
A17: Efficient frontier points | B17: 100 | C17: count | D17: config.py: n_frontier_points = 100. Number of target returns traced along the frontier.
A18: Random seed | B18: 42 | C18: int | D18: config.py: random_seed = 42. The seed used to generate the Monte Carlo weight draws on sheet '09 Monte Carlo'.
A21: PORTFOLIO HOLDINGS
A22: Read in Python from portfolio.xlsx (single 'Ticker' column) by data.load_tickers_from_excel(). Edit these cells to change the investable universe — every sheet follows automatically.
A23: # | B23: Ticker | C23: Asset
A24: 1 | B24: JPM | C24: JPMorgan Chase & Co.
A25: 2 | B25: MS | C25: Morgan Stanley
A26: 3 | B26: BAC | C26: Bank of America Corp.
A27: 4 | B27: AAPL | C27: Apple Inc.
A28: 5 | B28: MSFT | C28: Microsoft Corp.
A29: 6 | B29: GLD | C29: SPDR Gold Shares ETF
A32: COLOUR KEY
A33: Blue = hardcoded input you may edit
A34: Black = calculated by formula
A35: Green = link to another sheet

Sheet 03 Raw Data
A1: JPM | D1: MS | G1: BAC | J1: AAPL | M1: MSFT | P1: GLD | S1: BENCHMARK
A2: Date | B2: Close | D2: Date | E2: Close | G2: Date | H2: Close | J2: Date | K2: Close | M2: Date | N2: Close | P2: Date | Q2: Close | S2: Date | T2: Close
A3: {=_xlfn.STOCKHISTORY('02 Config'!$B$24,'02 Config'!$B$7,'02 Config'!$B$8,0,0,0,1)} | D3: {=_xlfn.STOCKHISTORY('02 Config'!$B$25,'02 Config'!$B$7,'02 Config'!$B$8,0,0,0,1)} | G3: {=_xlfn.STOCKHISTORY('02 Config'!$B$26,'02 Config'!$B$7,'02 Config'!$B$8,0,0,0,1)} | J3: {=_xlfn.STOCKHISTORY('02 Config'!$B$27,'02 Config'!$B$7,'02 Config'!$B$8,0,0,0,1)} | M3: {=_xlfn.STOCKHISTORY('02 Config'!$B$28,'02 Config'!$B$7,'02 Config'!$B$8,0,0,0,1)} | P3: {=_xlfn.STOCKHISTORY('02 Config'!$B$29,'02 Config'!$B$7,'02 Config'!$B$8,0,0,0,1)} | S3: {=_xlfn.STOCKHISTORY('02 Config'!$B$9,'02 Config'!$B$7,'02 Config'!$B$8,0,0,0,1)}
A4: NOTE: STOCKHISTORY requires a Microsoft 365 subscription and an internet connection. It returns the UNADJUSTED close, whereas the Python project uses Adj Close — dividend and split adjustments aside, the two differ slightly. Each block is a single array formula in its top-left cell.

Sheet 04 Prices
A1: Aligned Price Matrix
A2: The raw blocks are stitched onto one shared trading calendar with INDEX/MATCH, so every asset and the benchmark sit on the same row for the same date. This is the single price grid the whole model reads.
A3: Mirrors: data.download_prices() returning a DataFrame: columns = tickers, index = trading dates
A4: Date | B4: JPM | C4: MS | D4: BAC | E4: AAPL | F4: MSFT | G4: GLD | H4: BENCHMARK
A5: =IFERROR(IF(OR('03 Raw Data'!A3="",'03 Raw Data'!A3=0),"",'03 Raw Data'!A3),"") | B5: =IF($A5="","",IFERROR(INDEX('03 Raw Data'!$B$3:$B$722,MATCH($A5,'03 Raw Data'!$A$3:$A$722,0)),"")) | C5: =IF($A5="","",IFERROR(INDEX('03 Raw Data'!$E$3:$E$722,MATCH($A5,'03 Raw Data'!$D$3:$D$722,0)),"")) | D5: =IF($A5="","",IFERROR(INDEX('03 Raw Data'!$H$3:$H$722,MATCH($A5,'03 Raw Data'!$G$3:$G$722,0)),"")) | E5: =IF($A5="","",IFERROR(INDEX('03 Raw Data'!$K$3:$K$722,MATCH($A5,'03 Raw Data'!$J$3:$J$722,0)),"")) | F5: =IF($A5="","",IFERROR(INDEX('03 Raw Data'!$N$3:$N$722,MATCH($A5,'03 Raw Data'!$M$3:$M$722,0)),"")) | G5: =IF($A5="","",IFERROR(INDEX('03 Raw Data'!$Q$3:$Q$722,MATCH($A5,'03 Raw Data'!$P$3:$P$722,0)),"")) | H5: =IF($A5="","",IFERROR(INDEX('03 Raw Data'!$T$3:$T$722,MATCH($A5,'03 Raw Data'!$S$3:$S$722,0)),""))
A6: =IFERROR(IF(OR('03 Raw Data'!A4="",'03 Raw Data'!A4=0),"",'03 Raw Data'!A4),"") | B6: =IF($A6="","",IFERROR(INDEX('03 Raw Data'!$B$3:$B$722,MATCH($A6,'03 Raw Data'!$A$3:$A$722,0)),"")) | C6: =IF($A6="","",IFERROR(INDEX('03 Raw Data'!$E$3:$E$722,MATCH($A6,'03 Raw Data'!$D$3:$D$722,0)),"")) | D6: =IF($A6="","",IFERROR(INDEX('03 Raw Data'!$H$3:$H$722,MATCH($A6,'03 Raw Data'!$G$3:$G$722,0)),"")) | E6: =IF($A6="","",IFERROR(INDEX('03 Raw Data'!$K$3:$K$722,MATCH($A6,'03 Raw Data'!$J$3:$J$722,0)),"")) | F6: =IF($A6="","",IFERROR(INDEX('03 Raw Data'!$N$3:$N$722,MATCH($A6,'03 Raw Data'!$M$3:$M$722,0)),"")) | G6: =IF($A6="","",IFERROR(INDEX('03 Raw Data'!$Q$3:$Q$722,MATCH($A6,'03 Raw Data'!$P$3:$P$722,0)),"")) | H6: =IF($A6="","",IFERROR(INDEX('03 Raw Data'!$T$3:$T$722,MATCH($A6,'03 Raw Data'!$S$3:$S$722,0)),""))
A7: =IFERROR(IF(OR('03 Raw Data'!A5="",'03 Raw Data'!A5=0),"",'03 Raw Data'!A5),"") | B7: =IF($A7="","",IFERROR(INDEX('03 Raw Data'!$B$3:$B$722,MATCH($A7,'03 Raw Data'!$A$3:$A$722,0)),"")) | C7: =IF($A7="","",IFERROR(INDEX('03 Raw Data'!$E$3:$E$722,MATCH($A7,'03 Raw Data'!$D$3:$D$722,0)),"")) | D7: =IF($A7="","",IFERROR(INDEX('03 Raw Data'!$H$3:$H$722,MATCH($A7,'03 Raw Data'!$G$3:$G$722,0)),"")) | E7: =IF($A7="","",IFERROR(INDEX('03 Raw Data'!$K$3:$K$722,MATCH($A7,'03 Raw Data'!$J$3:$J$722,0)),"")) | F7: =IF($A7="","",IFERROR(INDEX('03 Raw Data'!$N$3:$N$722,MATCH($A7,'03 Raw Data'!$M$3:$M$722,0)),"")) | G7: =IF($A7="","",IFERROR(INDEX('03 Raw Data'!$Q$3:$Q$722,MATCH($A7,'03 Raw Data'!$P$3:$P$722,0)),"")) | H7: =IF($A7="","",IFERROR(INDEX('03 Raw Data'!$T$3:$T$722,MATCH($A7,'03 Raw Data'!$S$3:$S$722,0)),""))
A8: =IFERROR(IF(OR('03 Raw Data'!A6="",'03 Raw Data'!A6=0),"",'03 Raw Data'!A6),"") | B8: =IF($A8="","",IFERROR(INDEX('03 Raw Data'!$B$3:$B$722,MATCH($A8,'03 Raw Data'!$A$3:$A$722,0)),"")) | C8: =IF($A8="","",IFERROR(INDEX('03 Raw Data'!$E$3:$E$722,MATCH($A8,'03 Raw Data'!$D$3:$D$722,0)),"")) | D8: =IF($A8="","",IFERROR(INDEX('03 Raw Data'!$H$3:$H$722,MATCH($A8,'03 Raw Data'!$G$3:$G$722,0)),"")) | E8: =IF($A8="","",IFERROR(INDEX('03 Raw Data'!$K$3:$K$722,MATCH($A8,'03 Raw Data'!$J$3:$J$722,0)),"")) | F8: =IF($A8="","",IFERROR(INDEX('03 Raw Data'!$N$3:$N$722,MATCH($A8,'03 Raw Data'!$M$3:$M$722,0)),"")) | G8: =IF($A8="","",IFERROR(INDEX('03 Raw Data'!$Q$3:$Q$722,MATCH($A8,'03 Raw Data'!$P$3:$P$722,0)),"")) | H8: =IF($A8="","",IFERROR(INDEX('03 Raw Data'!$T$3:$T$722,MATCH($A8,'03 Raw Data'!$S$3:$S$722,0)),""))
A9: =IFERROR(IF(OR('03 Raw Data'!A7="",'03 Raw Data'!A7=0),"",'03 Raw Data'!A7),"") | B9: =IF($A9="","",IFERROR(INDEX('03 Raw Data'!$B$3:$B$722,MATCH($A9,'03 Raw Data'!$A$3:$A$722,0)),"")) | C9: =IF($A9="","",IFERROR(INDEX('03 Raw Data'!$E$3:$E$722,MATCH($A9,'03 Raw Data'!$D$3:$D$722,0)),"")) | D9: =IF($A9="","",IFERROR(INDEX('03 Raw Data'!$H$3:$H$722,MATCH($A9,'03 Raw Data'!$G$3:$G$722,0)),"")) | E9: =IF($A9="","",IFERROR(INDEX('03 Raw Data'!$K$3:$K$722,MATCH($A9,'03 Raw Data'!$J$3:$J$722,0)),"")) | F9: =IF($A9="","",IFERROR(INDEX('03 Raw Data'!$N$3:$N$722,MATCH($A9,'03 Raw Data'!$M$3:$M$722,0)),"")) | G9: =IF($A9="","",IFERROR(INDEX('03 Raw Data'!$Q$3:$Q$722,MATCH($A9,'03 Raw Data'!$P$3:$P$722,0)),"")) | H9: =IF($A9="","",IFERROR(INDEX('03 Raw Data'!$T$3:$T$722,MATCH($A9,'03 Raw Data'!$S$3:$S$722,0)),""))
A10: =IFERROR(IF(OR('03 Raw Data'!A8="",'03 Raw Data'!A8=0),"",'03 Raw Data'!A8),"") | B10: =IF($A10="","",IFERROR(INDEX('03 Raw Data'!$B$3:$B$722,MATCH($A10,'03 Raw Data'!$A$3:$A$722,0)),"")) | C10: =IF($A10="","",IFERROR(INDEX('03 Raw Data'!$E$3:$E$722,MATCH($A10,'03 Raw Data'!$D$3:$D$722,0)),"")) | D10: =IF($A10="","",IFERROR(INDEX('03 Raw Data'!$H$3:$H$722,MATCH($A10,'03 Raw Data'!$G$3:$G$722,0)),"")) | E10: =IF($A10="","",IFERROR(INDEX('03 Raw Data'!$K$3:$K$722,MATCH($A10,'03 Raw Data'!$J$3:$J$722,0)),"")) | F10: =IF($A10="","",IFERROR(INDEX('03 Raw Data'!$N$3:$N$722,MATCH($A10,'03 Raw Data'!$M$3:$M$722,0)),"")) | G10: =IF($A10="","",IFERROR(INDEX('03 Raw Data'!$Q$3:$Q$722,MATCH($A10,'03 Raw Data'!$P$3:$P$722,0)),"")) | H10: =IF($A10="","",IFERROR(INDEX('03 Raw Data'!$T$3:$T$722,MATCH($A10,'03 Raw Data'!$S$3:$S$722,0)),""))
A11: =IFERROR(IF(OR('03 Raw Data'!A9="",'03 Raw Data'!A9=0),"",'03 Raw Data'!A9),"") | B11: =IF($A11="","",IFERROR(INDEX('03 Raw Data'!$B$3:$B$722,MATCH($A11,'03 Raw Data'!$A$3:$A$722,0)),"")) | C11: =IF($A11="","",IFERROR(INDEX('03 Raw Data'!$E$3:$E$722,MATCH($A11,'03 Raw Data'!$D$3:$D$722,0)),"")) | D11: =IF($A11="","",IFERROR(INDEX('03 Raw Data'!$H$3:$H$722,MATCH($A11,'03 Raw Data'!$G$3:$G$722,0)),"")) | E11: =IF($A11="","",IFERROR(INDEX('03 Raw Data'!$K$3:$K$722,MATCH($A11,'03 Raw Data'!$J$3:$J$722,0)),"")) | F11: =IF($A11="","",IFERROR(INDEX('03 Raw Data'!$N$3:$N$722,MATCH($A11,'03 Raw Data'!$M$3:$M$722,0)),"")) | G11: =IF($A11="","",IFERROR(INDEX('03 Raw Data'!$Q$3:$Q$722,MATCH($A11,'03 Raw Data'!$P$3:$P$722,0)),"")) | H11: =IF($A11="","",IFERROR(INDEX('03 Raw Data'!$T$3:$T$722,MATCH($A11,'03 Raw Data'!$S$3:$S$722,0)),""))
A12: =IFERROR(IF(OR('03 Raw Data'!A10="",'03 Raw Data'!A10=0),"",'03 Raw Data'!A10),"") | B12: =IF($A12="","",IFERROR(INDEX('03 Raw Data'!$B$3:$B$722,MATCH($A12,'03 Raw Data'!$A$3:$A$722,0)),"")) | C12: =IF($A12="","",IFERROR(INDEX('03 Raw Data'!$E$3:$E$722,MATCH($A12,'03 Raw Data'!$D$3:$D$722,0)),"")) | D12: =IF($A12="","",IFERROR(INDEX('03 Raw Data'!$H$3:$H$722,MATCH($A12,'03 Raw Data'!$G$3:$G$722,0)),"")) | E12: =IF($A12="","",IFERROR(INDEX('03 Raw Data'!$K$3:$K$722,MATCH($A12,'03 Raw Data'!$J$3:$J$722,0)),"")) | F12: =IF($A12="","",IFERROR(INDEX('03 Raw Data'!$N$3:$N$722,MATCH($A12,'03 Raw Data'!$M$3:$M$722,0)),"")) | G12: =IF($A12="","",IFERROR(INDEX('03 Raw Data'!$Q$3:$Q$722,MATCH($A12,'03 Raw Data'!$P$3:$P$722,0)),"")) | H12: =IF($A12="","",IFERROR(INDEX('03 Raw Data'!$T$3:$T$722,MATCH($A12,'03 Raw Data'!$S$3:$S$722,0)),""))
A13: =IFERROR(IF(OR('03 Raw Data'!A11="",'03 Raw Data'!A11=0),"",'03 Raw Data'!A11),"") | B13: =IF($A13="","",IFERROR(INDEX('03 Raw Data'!$B$3:$B$722,MATCH($A13,'03 Raw Data'!$A$3:$A$722,0)),"")) | C13: =IF($A13="","",IFERROR(INDEX('03 Raw Data'!$E$3:$E$722,MATCH($A13,'03 Raw Data'!$D$3:$D$722,0)),"")) | D13: =IF($A13="","",IFERROR(INDEX('03 Raw Data'!$H$3:$H$722,MATCH($A13,'03 Raw Data'!$G$3:$G$722,0)),"")) | E13: =IF($A13="","",IFERROR(INDEX('03 Raw Data'!$K$3:$K$722,MATCH($A13,'03 Raw Data'!$J$3:$J$722,0)),"")) | F13: =IF($A13="","",IFERROR(INDEX('03 Raw Data'!$N$3:$N$722,MATCH($A13,'03 Raw Data'!$M$3:$M$722,0)),"")) | G13: =IF($A13="","",IFERROR(INDEX('03 Raw Data'!$Q$3:$Q$722,MATCH($A13,'03 Raw Data'!$P$3:$P$722,0)),"")) | H13: =IF($A13="","",IFERROR(INDEX('03 Raw Data'!$T$3:$T$722,MATCH($A13,'03 Raw Data'!$S$3:$S$722,0)),""))
A14: =IFERROR(IF(OR('03 Raw Data'!A12="",'03 Raw Data'!A12=0),"",'03 Raw Data'!A12),"") | B14: =IF($A14="","",IFERROR(INDEX('03 Raw Data'!$B$3:$B$722,MATCH($A14,'03 Raw Data'!$A$3:$A$722,0)),"")) | C14: =IF($A14="","",IFERROR(INDEX('03 Raw Data'!$E$3:$E$722,MATCH($A14,'03 Raw Data'!$D$3:$D$722,0)),"")) | D14: =IF($A14="","",IFERROR(INDEX('03 Raw Data'!$H$3:$H$722,MATCH($A14,'03 Raw Data'!$G$3:$G$722,0)),"")) | E14: =IF($A14="","",IFERROR(INDEX('03 Raw Data'!$K$3:$K$722,MATCH($A14,'03 Raw Data'!$J$3:$J$722,0)),"")) | F14: =IF($A14="","",IFERROR(INDEX('03 Raw Data'!$N$3:$N$722,MATCH($A14,'03 Raw Data'!$M$3:$M$722,0)),"")) | G14: =IF($A14="","",IFERROR(INDEX('03 Raw Data'!$Q$3:$Q$722,MATCH($A14,'03 Raw Data'!$P$3:$P$722,0)),"")) | H14: =IF($A14="","",IFERROR(INDEX('03 Raw Data'!$T$3:$T$722,MATCH($A14,'03 Raw Data'!$S$3:$S$722,0)),""))
A15: =IFERROR(IF(OR('03 Raw Data'!A13="",'03 Raw Data'!A13=0),"",'03 Raw Data'!A13),"") | B15: =IF($A15="","",IFERROR(INDEX('03 Raw Data'!$B$3:$B$722,MATCH($A15,'03 Raw Data'!$A$3:$A$722,0)),"")) | C15: =IF($A15="","",IFERROR(INDEX('03 Raw Data'!$E$3:$E$722,MATCH($A15,'03 Raw Data'!$D$3:$D$722,0)),"")) | D15: =IF($A15="","",IFERROR(INDEX('03 Raw Data'!$H$3:$H$722,MATCH($A15,'03 Raw Data'!$G$3:$G$722,0)),"")) | E15: =IF($A15="","",IFERROR(INDEX('03 Raw Data'!$K$3:$K$722,MATCH($A15,'03 Raw Data'!$J$3:$J$722,0)),"")) | F15: =IF($A15="","",IFERROR(INDEX('03 Raw Data'!$N$3:$N$722,MATCH($A15,'03 Raw Data'!$M$3:$M$722,0)),"")) | G15: =IF($A15="","",IFERROR(INDEX('03 Raw Data'!$Q$3:$Q$722,MATCH($A15,'03 Raw Data'!$P$3:$P$722,0)),"")) | H15: =IF($A15="","",IFERROR(INDEX('03 Raw Data'!$T$3:$T$722,MATCH($A15,'03 Raw Data'!$S$3:$S$722,0)),""))
A16: =IFERROR(IF(OR('03 Raw Data'!A14="",'03 Raw Data'!A14=0),"",'03 Raw Data'!A14),"") | B16: =IF($A16="","",IFERROR(INDEX('03 Raw Data'!$B$3:$B$722,MATCH($A16,'03 Raw Data'!$A$3:$A$722,0)),"")) | C16: =IF($A16="","",IFERROR(INDEX('03 Raw Data'!$E$3:$E$722,MATCH($A16,'03 Raw Data'!$D$3:$D$722,0)),"")) | D16: =IF($A16="","",IFERROR(INDEX('03 Raw Data'!$H$3:$H$722,MATCH($A16,'03 Raw Data'!$G$3:$G$722,0)),"")) | E16: =IF($A16="","",IFERROR(INDEX('03 Raw Data'!$K$3:$K$722,MATCH($A16,'03 Raw Data'!$J$3:$J$722,0)),"")) | F16: =IF($A16="","",IFERROR(INDEX('03 Raw Data'!$N$3:$N$722,MATCH($A16,'03 Raw Data'!$M$3:$M$722,0)),"")) | G16: =IF($A16="","",IFERROR(INDEX('03 Raw Data'!$Q$3:$Q$722,MATCH($A16,'03 Raw Data'!$P$3:$P$722,0)),"")) | H16: =IF($A16="","",IFERROR(INDEX('03 Raw Data'!$T$3:$T$722,MATCH($A16,'03 Raw Data'!$S$3:$S$722,0)),""))
... A724: =IFERROR(IF(OR('03 Raw Data'!A722="",'03 Raw Data'!A722=0),"",'03 Raw Data'!A722),"") | B724: =IF($A724="","",IFERROR(INDEX('03 Raw Data'!$B$3:$B$722,MATCH($A724,'03 Raw Data'!$A$3:$A$722,0)),"")) | C724: =IF($A724="","",IFERROR(INDEX('03 Raw Data'!$E$3:$E$722,MATCH($A724,'03 Raw Data'!$D$3:$D$722,0)),"")) | D724: =IF($A724="","",IFERROR(INDEX('03 Raw Data'!$H$3:$H$722,MATCH($A724,'03 Raw Data'!$G$3:$G$722,0)),"")) | E724: =IF($A724="","",IFERROR(INDEX('03 Raw Data'!$K$3:$K$722,MATCH($A724,'03 Raw Data'!$J$3:$J$722,0)),"")) | F724: =IF($A724="","",IFERROR(INDEX('03 Raw Data'!$N$3:$N$722,MATCH($A724,'03 Raw Data'!$M$3:$M$722,0)),"")) | G724: =IF($A724="","",IFERROR(INDEX('03 Raw Data'!$Q$3:$Q$722,MATCH($A724,'03 Raw Data'!$P$3:$P$722,0)),"")) | H724: =IF($A724="","",IFERROR(INDEX('03 Raw Data'!$T$3:$T$722,MATCH($A724,'03 Raw Data'!$S$3:$S$722,0)),""))

Sheet 05 Simple Returns
A1: Daily Simple (Arithmetic) Returns
A2: r_t = P_t / P_(t-1) - 1, one row per trading day after the first. Simple returns aggregate correctly ACROSS ASSETS, which is why the portfolio return series and every risk metric are built from these.
A3: Mirrors: returns.py -> simple_returns(prices) = prices.pct_change().dropna()
A4: Date | B4: JPM | C4: MS | D4: BAC | E4: AAPL | F4: MSFT | G4: GLD | H4: BENCHMARK
A5: =IF('04 Prices'!A6="","",'04 Prices'!A6) | B5: =IF(OR($A5="",'04 Prices'!B5="",'04 Prices'!B6=""),"",'04 Prices'!B6/'04 Prices'!B5-1) | C5: =IF(OR($A5="",'04 Prices'!C5="",'04 Prices'!C6=""),"",'04 Prices'!C6/'04 Prices'!C5-1) | D5: =IF(OR($A5="",'04 Prices'!D5="",'04 Prices'!D6=""),"",'04 Prices'!D6/'04 Prices'!D5-1) | E5: =IF(OR($A5="",'04 Prices'!E5="",'04 Prices'!E6=""),"",'04 Prices'!E6/'04 Prices'!E5-1) | F5: =IF(OR($A5="",'04 Prices'!F5="",'04 Prices'!F6=""),"",'04 Prices'!F6/'04 Prices'!F5-1) | G5: =IF(OR($A5="",'04 Prices'!G5="",'04 Prices'!G6=""),"",'04 Prices'!G6/'04 Prices'!G5-1) | H5: =IF(OR($A5="",'04 Prices'!H5="",'04 Prices'!H6=""),"",'04 Prices'!H6/'04 Prices'!H5-1)
A6: =IF('04 Prices'!A7="","",'04 Prices'!A7) | B6: =IF(OR($A6="",'04 Prices'!B6="",'04 Prices'!B7=""),"",'04 Prices'!B7/'04 Prices'!B6-1) | C6: =IF(OR($A6="",'04 Prices'!C6="",'04 Prices'!C7=""),"",'04 Prices'!C7/'04 Prices'!C6-1) | D6: =IF(OR($A6="",'04 Prices'!D6="",'04 Prices'!D7=""),"",'04 Prices'!D7/'04 Prices'!D6-1) | E6: =IF(OR($A6="",'04 Prices'!E6="",'04 Prices'!E7=""),"",'04 Prices'!E7/'04 Prices'!E6-1) | F6: =IF(OR($A6="",'04 Prices'!F6="",'04 Prices'!F7=""),"",'04 Prices'!F7/'04 Prices'!F6-1) | G6: =IF(OR($A6="",'04 Prices'!G6="",'04 Prices'!G7=""),"",'04 Prices'!G7/'04 Prices'!G6-1) | H6: =IF(OR($A6="",'04 Prices'!H6="",'04 Prices'!H7=""),"",'04 Prices'!H7/'04 Prices'!H6-1)
A7: =IF('04 Prices'!A8="","",'04 Prices'!A8) | B7: =IF(OR($A7="",'04 Prices'!B7="",'04 Prices'!B8=""),"",'04 Prices'!B8/'04 Prices'!B7-1) | C7: =IF(OR($A7="",'04 Prices'!C7="",'04 Prices'!C8=""),"",'04 Prices'!C8/'04 Prices'!C7-1) | D7: =IF(OR($A7="",'04 Prices'!D7="",'04 Prices'!D8=""),"",'04 Prices'!D8/'04 Prices'!D7-1) | E7: =IF(OR($A7="",'04 Prices'!E7="",'04 Prices'!E8=""),"",'04 Prices'!E8/'04 Prices'!E7-1) | F7: =IF(OR($A7="",'04 Prices'!F7="",'04 Prices'!F8=""),"",'04 Prices'!F8/'04 Prices'!F7-1) | G7: =IF(OR($A7="",'04 Prices'!G7="",'04 Prices'!G8=""),"",'04 Prices'!G8/'04 Prices'!G7-1) | H7: =IF(OR($A7="",'04 Prices'!H7="",'04 Prices'!H8=""),"",'04 Prices'!H8/'04 Prices'!H7-1)
A8: =IF('04 Prices'!A9="","",'04 Prices'!A9) | B8: =IF(OR($A8="",'04 Prices'!B8="",'04 Prices'!B9=""),"",'04 Prices'!B9/'04 Prices'!B8-1) | C8: =IF(OR($A8="",'04 Prices'!C8="",'04 Prices'!C9=""),"",'04 Prices'!C9/'04 Prices'!C8-1) | D8: =IF(OR($A8="",'04 Prices'!D8="",'04 Prices'!D9=""),"",'04 Prices'!D9/'04 Prices'!D8-1) | E8: =IF(OR($A8="",'04 Prices'!E8="",'04 Prices'!E9=""),"",'04 Prices'!E9/'04 Prices'!E8-1) | F8: =IF(OR($A8="",'04 Prices'!F8="",'04 Prices'!F9=""),"",'04 Prices'!F9/'04 Prices'!F8-1) | G8: =IF(OR($A8="",'04 Prices'!G8="",'04 Prices'!G9=""),"",'04 Prices'!G9/'04 Prices'!G8-1) | H8: =IF(OR($A8="",'04 Prices'!H8="",'04 Prices'!H9=""),"",'04 Prices'!H9/'04 Prices'!H8-1)
A9: =IF('04 Prices'!A10="","",'04 Prices'!A10) | B9: =IF(OR($A9="",'04 Prices'!B9="",'04 Prices'!B10=""),"",'04 Prices'!B10/'04 Prices'!B9-1) | C9: =IF(OR($A9="",'04 Prices'!C9="",'04 Prices'!C10=""),"",'04 Prices'!C10/'04 Prices'!C9-1) | D9: =IF(OR($A9="",'04 Prices'!D9="",'04 Prices'!D10=""),"",'04 Prices'!D10/'04 Prices'!D9-1) | E9: =IF(OR($A9="",'04 Prices'!E9="",'04 Prices'!E10=""),"",'04 Prices'!E10/'04 Prices'!E9-1) | F9: =IF(OR($A9="",'04 Prices'!F9="",'04 Prices'!F10=""),"",'04 Prices'!F10/'04 Prices'!F9-1) | G9: =IF(OR($A9="",'04 Prices'!G9="",'04 Prices'!G10=""),"",'04 Prices'!G10/'04 Prices'!G9-1) | H9: =IF(OR($A9="",'04 Prices'!H9="",'04 Prices'!H10=""),"",'04 Prices'!H10/'04 Prices'!H9-1)
A10: =IF('04 Prices'!A11="","",'04 Prices'!A11) | B10: =IF(OR($A10="",'04 Prices'!B10="",'04 Prices'!B11=""),"",'04 Prices'!B11/'04 Prices'!B10-1) | C10: =IF(OR($A10="",'04 Prices'!C10="",'04 Prices'!C11=""),"",'04 Prices'!C11/'04 Prices'!C10-1) | D10: =IF(OR($A10="",'04 Prices'!D10="",'04 Prices'!D11=""),"",'04 Prices'!D11/'04 Prices'!D10-1) | E10: =IF(OR($A10="",'04 Prices'!E10="",'04 Prices'!E11=""),"",'04 Prices'!E11/'04 Prices'!E10-1) | F10: =IF(OR($A10="",'04 Prices'!F10="",'04 Prices'!F11=""),"",'04 Prices'!F11/'04 Prices'!F10-1) | G10: =IF(OR($A10="",'04 Prices'!G10="",'04 Prices'!G11=""),"",'04 Prices'!G11/'04 Prices'!G10-1) | H10: =IF(OR($A10="",'04 Prices'!H10="",'04 Prices'!H11=""),"",'04 Prices'!H11/'04 Prices'!H10-1)
A11: =IF('04 Prices'!A12="","",'04 Prices'!A12) | B11: =IF(OR($A11="",'04 Prices'!B11="",'04 Prices'!B12=""),"",'04 Prices'!B12/'04 Prices'!B11-1) | C11: =IF(OR($A11="",'04 Prices'!C11="",'04 Prices'!C12=""),"",'04 Prices'!C12/'04 Prices'!C11-1) | D11: =IF(OR($A11="",'04 Prices'!D11="",'04 Prices'!D12=""),"",'04 Prices'!D12/'04 Prices'!D11-1) | E11: =IF(OR($A11="",'04 Prices'!E11="",'04 Prices'!E12=""),"",'04 Prices'!E12/'04 Prices'!E11-1) | F11: =IF(OR($A11="",'04 Prices'!F11="",'04 Prices'!F12=""),"",'04 Prices'!F12/'04 Prices'!F11-1) | G11: =IF(OR($A11="",'04 Prices'!G11="",'04 Prices'!G12=""),"",'04 Prices'!G12/'04 Prices'!G11-1) | H11: =IF(OR($A11="",'04 Prices'!H11="",'04 Prices'!H12=""),"",'04 Prices'!H12/'04 Prices'!H11-1)
A12: =IF('04 Prices'!A13="","",'04 Prices'!A13) | B12: =IF(OR($A12="",'04 Prices'!B12="",'04 Prices'!B13=""),"",'04 Prices'!B13/'04 Prices'!B12-1) | C12: =IF(OR($A12="",'04 Prices'!C12="",'04 Prices'!C13=""),"",'04 Prices'!C13/'04 Prices'!C12-1) | D12: =IF(OR($A12="",'04 Prices'!D12="",'04 Prices'!D13=""),"",'04 Prices'!D13/'04 Prices'!D12-1) | E12: =IF(OR($A12="",'04 Prices'!E12="",'04 Prices'!E13=""),"",'04 Prices'!E13/'04 Prices'!E12-1) | F12: =IF(OR($A12="",'04 Prices'!F12="",'04 Prices'!F13=""),"",'04 Prices'!F13/'04 Prices'!F12-1) | G12: =IF(OR($A12="",'04 Prices'!G12="",'04 Prices'!G13=""),"",'04 Prices'!G13/'04 Prices'!G12-1) | H12: =IF(OR($A12="",'04 Prices'!H12="",'04 Prices'!H13=""),"",'04 Prices'!H13/'04 Prices'!H12-1)
A13: =IF('04 Prices'!A14="","",'04 Prices'!A14) | B13: =IF(OR($A13="",'04 Prices'!B13="",'04 Prices'!B14=""),"",'04 Prices'!B14/'04 Prices'!B13-1) | C13: =IF(OR($A13="",'04 Prices'!C13="",'04 Prices'!C14=""),"",'04 Prices'!C14/'04 Prices'!C13-1) | D13: =IF(OR($A13="",'04 Prices'!D13="",'04 Prices'!D14=""),"",'04 Prices'!D14/'04 Prices'!D13-1) | E13: =IF(OR($A13="",'04 Prices'!E13="",'04 Prices'!E14=""),"",'04 Prices'!E14/'04 Prices'!E13-1) | F13: =IF(OR($A13="",'04 Prices'!F13="",'04 Prices'!F14=""),"",'04 Prices'!F14/'04 Prices'!F13-1) | G13: =IF(OR($A13="",'04 Prices'!G13="",'04 Prices'!G14=""),"",'04 Prices'!G14/'04 Prices'!G13-1) | H13: =IF(OR($A13="",'04 Prices'!H13="",'04 Prices'!H14=""),"",'04 Prices'!H14/'04 Prices'!H13-1)
A14: =IF('04 Prices'!A15="","",'04 Prices'!A15) | B14: =IF(OR($A14="",'04 Prices'!B14="",'04 Prices'!B15=""),"",'04 Prices'!B15/'04 Prices'!B14-1) | C14: =IF(OR($A14="",'04 Prices'!C14="",'04 Prices'!C15=""),"",'04 Prices'!C15/'04 Prices'!C14-1) | D14: =IF(OR($A14="",'04 Prices'!D14="",'04 Prices'!D15=""),"",'04 Prices'!D15/'04 Prices'!D14-1) | E14: =IF(OR($A14="",'04 Prices'!E14="",'04 Prices'!E15=""),"",'04 Prices'!E15/'04 Prices'!E14-1) | F14: =IF(OR($A14="",'04 Prices'!F14="",'04 Prices'!F15=""),"",'04 Prices'!F15/'04 Prices'!F14-1) | G14: =IF(OR($A14="",'04 Prices'!G14="",'04 Prices'!G15=""),"",'04 Prices'!G15/'04 Prices'!G14-1) | H14: =IF(OR($A14="",'04 Prices'!H14="",'04 Prices'!H15=""),"",'04 Prices'!H15/'04 Prices'!H14-1)
A15: =IF('04 Prices'!A16="","",'04 Prices'!A16) | B15: =IF(OR($A15="",'04 Prices'!B15="",'04 Prices'!B16=""),"",'04 Prices'!B16/'04 Prices'!B15-1) | C15: =IF(OR($A15="",'04 Prices'!C15="",'04 Prices'!C16=""),"",'04 Prices'!C16/'04 Prices'!C15-1) | D15: =IF(OR($A15="",'04 Prices'!D15="",'04 Prices'!D16=""),"",'04 Prices'!D16/'04 Prices'!D15-1) | E15: =IF(OR($A15="",'04 Prices'!E15="",'04 Prices'!E16=""),"",'04 Prices'!E16/'04 Prices'!E15-1) | F15: =IF(OR($A15="",'04 Prices'!F15="",'04 Prices'!F16=""),"",'04 Prices'!F16/'04 Prices'!F15-1) | G15: =IF(OR($A15="",'04 Prices'!G15="",'04 Prices'!G16=""),"",'04 Prices'!G16/'04 Prices'!G15-1) | H15: =IF(OR($A15="",'04 Prices'!H15="",'04 Prices'!H16=""),"",'04 Prices'!H16/'04 Prices'!H15-1)
A16: =IF('04 Prices'!A17="","",'04 Prices'!A17) | B16: =IF(OR($A16="",'04 Prices'!B16="",'04 Prices'!B17=""),"",'04 Prices'!B17/'04 Prices'!B16-1) | C16: =IF(OR($A16="",'04 Prices'!C16="",'04 Prices'!C17=""),"",'04 Prices'!C17/'04 Prices'!C16-1) | D16: =IF(OR($A16="",'04 Prices'!D16="",'04 Prices'!D17=""),"",'04 Prices'!D17/'04 Prices'!D16-1) | E16: =IF(OR($A16="",'04 Prices'!E16="",'04 Prices'!E17=""),"",'04 Prices'!E17/'04 Prices'!E16-1) | F16: =IF(OR($A16="",'04 Prices'!F16="",'04 Prices'!F17=""),"",'04 Prices'!F17/'04 Prices'!F16-1) | G16: =IF(OR($A16="",'04 Prices'!G16="",'04 Prices'!G17=""),"",'04 Prices'!G17/'04 Prices'!G16-1) | H16: =IF(OR($A16="",'04 Prices'!H16="",'04 Prices'!H17=""),"",'04 Prices'!H17/'04 Prices'!H16-1)
... A723: =IF('04 Prices'!A724="","",'04 Prices'!A724) | B723: =IF(OR($A723="",'04 Prices'!B723="",'04 Prices'!B724=""),"",'04 Prices'!B724/'04 Prices'!B723-1) | C723: =IF(OR($A723="",'04 Prices'!C723="",'04 Prices'!C724=""),"",'04 Prices'!C724/'04 Prices'!C723-1) | D723: =IF(OR($A723="",'04 Prices'!D723="",'04 Prices'!D724=""),"",'04 Prices'!D724/'04 Prices'!D723-1) | E723: =IF(OR($A723="",'04 Prices'!E723="",'04 Prices'!E724=""),"",'04 Prices'!E724/'04 Prices'!E723-1) | F723: =IF(OR($A723="",'04 Prices'!F723="",'04 Prices'!F724=""),"",'04 Prices'!F724/'04 Prices'!F723-1) | G723: =IF(OR($A723="",'04 Prices'!G723="",'04 Prices'!G724=""),"",'04 Prices'!G724/'04 Prices'!G723-1) | H723: =IF(OR($A723="",'04 Prices'!H723="",'04 Prices'!H724=""),"",'04 Prices'!H724/'04 Prices'!H723-1)

Sheet 06 Log Returns
A1: Daily Logarithmic (Continuously Compounded) Returns
A2: r_t = ln(P_t / P_(t-1)). Log returns add up ACROSS TIME, which makes them the right input for annualising and for the covariance matrix that drives the Markowitz optimisation.
A3: Mirrors: returns.py -> log_returns(prices) = np.log(prices / prices.shift(1)).dropna()
A4: Date | B4: JPM | C4: MS | D4: BAC | E4: AAPL | F4: MSFT | G4: GLD | H4: BENCHMARK
A5: =IF('04 Prices'!A6="","",'04 Prices'!A6) | B5: =IF(OR($A5="",'04 Prices'!B5="",'04 Prices'!B6=""),"",LN('04 Prices'!B6/'04 Prices'!B5)) | C5: =IF(OR($A5="",'04 Prices'!C5="",'04 Prices'!C6=""),"",LN('04 Prices'!C6/'04 Prices'!C5)) | D5: =IF(OR($A5="",'04 Prices'!D5="",'04 Prices'!D6=""),"",LN('04 Prices'!D6/'04 Prices'!D5)) | E5: =IF(OR($A5="",'04 Prices'!E5="",'04 Prices'!E6=""),"",LN('04 Prices'!E6/'04 Prices'!E5)) | F5: =IF(OR($A5="",'04 Prices'!F5="",'04 Prices'!F6=""),"",LN('04 Prices'!F6/'04 Prices'!F5)) | G5: =IF(OR($A5="",'04 Prices'!G5="",'04 Prices'!G6=""),"",LN('04 Prices'!G6/'04 Prices'!G5)) | H5: =IF(OR($A5="",'04 Prices'!H5="",'04 Prices'!H6=""),"",LN('04 Prices'!H6/'04 Prices'!H5))
A6: =IF('04 Prices'!A7="","",'04 Prices'!A7) | B6: =IF(OR($A6="",'04 Prices'!B6="",'04 Prices'!B7=""),"",LN('04 Prices'!B7/'04 Prices'!B6)) | C6: =IF(OR($A6="",'04 Prices'!C6="",'04 Prices'!C7=""),"",LN('04 Prices'!C7/'04 Prices'!C6)) | D6: =IF(OR($A6="",'04 Prices'!D6="",'04 Prices'!D7=""),"",LN('04 Prices'!D7/'04 Prices'!D6)) | E6: =IF(OR($A6="",'04 Prices'!E6="",'04 Prices'!E7=""),"",LN('04 Prices'!E7/'04 Prices'!E6)) | F6: =IF(OR($A6="",'04 Prices'!F6="",'04 Prices'!F7=""),"",LN('04 Prices'!F7/'04 Prices'!F6)) | G6: =IF(OR($A6="",'04 Prices'!G6="",'04 Prices'!G7=""),"",LN('04 Prices'!G7/'04 Prices'!G6)) | H6: =IF(OR($A6="",'04 Prices'!H6="",'04 Prices'!H7=""),"",LN('04 Prices'!H7/'04 Prices'!H6))
A7: =IF('04 Prices'!A8="","",'04 Prices'!A8) | B7: =IF(OR($A7="",'04 Prices'!B7="",'04 Prices'!B8=""),"",LN('04 Prices'!B8/'04 Prices'!B7)) | C7: =IF(OR($A7="",'04 Prices'!C7="",'04 Prices'!C8=""),"",LN('04 Prices'!C8/'04 Prices'!C7)) | D7: =IF(OR($A7="",'04 Prices'!D7="",'04 Prices'!D8=""),"",LN('04 Prices'!D8/'04 Prices'!D7)) | E7: =IF(OR($A7="",'04 Prices'!E7="",'04 Prices'!E8=""),"",LN('04 Prices'!E8/'04 Prices'!E7)) | F7: =IF(OR($A7="",'04 Prices'!F7="",'04 Prices'!F8=""),"",LN('04 Prices'!F8/'04 Prices'!F7)) | G7: =IF(OR($A7="",'04 Prices'!G7="",'04 Prices'!G8=""),"",LN('04 Prices'!G8/'04 Prices'!G7)) | H7: =IF(OR($A7="",'04 Prices'!H7="",'04 Prices'!H8=""),"",LN('04 Prices'!H8/'04 Prices'!H7))
A8: =IF('04 Prices'!A9="","",'04 Prices'!A9) | B8: =IF(OR($A8="",'04 Prices'!B8="",'04 Prices'!B9=""),"",LN('04 Prices'!B9/'04 Prices'!B8)) | C8: =IF(OR($A8="",'04 Prices'!C8="",'04 Prices'!C9=""),"",LN('04 Prices'!C9/'04 Prices'!C8)) | D8: =IF(OR($A8="",'04 Prices'!D8="",'04 Prices'!D9=""),"",LN('04 Prices'!D9/'04 Prices'!D8)) | E8: =IF(OR($A8="",'04 Prices'!E8="",'04 Prices'!E9=""),"",LN('04 Prices'!E9/'04 Prices'!E8)) | F8: =IF(OR($A8="",'04 Prices'!F8="",'04 Prices'!F9=""),"",LN('04 Prices'!F9/'04 Prices'!F8)) | G8: =IF(OR($A8="",'04 Prices'!G8="",'04 Prices'!G9=""),"",LN('04 Prices'!G9/'04 Prices'!G8)) | H8: =IF(OR($A8="",'04 Prices'!H8="",'04 Prices'!H9=""),"",LN('04 Prices'!H9/'04 Prices'!H8))
A9: =IF('04 Prices'!A10="","",'04 Prices'!A10) | B9: =IF(OR($A9="",'04 Prices'!B9="",'04 Prices'!B10=""),"",LN('04 Prices'!B10/'04 Prices'!B9)) | C9: =IF(OR($A9="",'04 Prices'!C9="",'04 Prices'!C10=""),"",LN('04 Prices'!C10/'04 Prices'!C9)) | D9: =IF(OR($A9="",'04 Prices'!D9="",'04 Prices'!D10=""),"",LN('04 Prices'!D10/'04 Prices'!D9)) | E9: =IF(OR($A9="",'04 Prices'!E9="",'04 Prices'!E10=""),"",LN('04 Prices'!E10/'04 Prices'!E9)) | F9: =IF(OR($A9="",'04 Prices'!F9="",'04 Prices'!F10=""),"",LN('04 Prices'!F10/'04 Prices'!F9)) | G9: =IF(OR($A9="",'04 Prices'!G9="",'04 Prices'!G10=""),"",LN('04 Prices'!G10/'04 Prices'!G9)) | H9: =IF(OR($A9="",'04 Prices'!H9="",'04 Prices'!H10=""),"",LN('04 Prices'!H10/'04 Prices'!H9))
A10: =IF('04 Prices'!A11="","",'04 Prices'!A11) | B10: =IF(OR($A10="",'04 Prices'!B10="",'04 Prices'!B11=""),"",LN('04 Prices'!B11/'04 Prices'!B10)) | C10: =IF(OR($A10="",'04 Prices'!C10="",'04 Prices'!C11=""),"",LN('04 Prices'!C11/'04 Prices'!C10)) | D10: =IF(OR($A10="",'04 Prices'!D10="",'04 Prices'!D11=""),"",LN('04 Prices'!D11/'04 Prices'!D10)) | E10: =IF(OR($A10="",'04 Prices'!E10="",'04 Prices'!E11=""),"",LN('04 Prices'!E11/'04 Prices'!E10)) | F10: =IF(OR($A10="",'04 Prices'!F10="",'04 Prices'!F11=""),"",LN('04 Prices'!F11/'04 Prices'!F10)) | G10: =IF(OR($A10="",'04 Prices'!G10="",'04 Prices'!G11=""),"",LN('04 Prices'!G11/'04 Prices'!G10)) | H10: =IF(OR($A10="",'04 Prices'!H10="",'04 Prices'!H11=""),"",LN('04 Prices'!H11/'04 Prices'!H10))
A11: =IF('04 Prices'!A12="","",'04 Prices'!A12) | B11: =IF(OR($A11="",'04 Prices'!B11="",'04 Prices'!B12=""),"",LN('04 Prices'!B12/'04 Prices'!B11)) | C11: =IF(OR($A11="",'04 Prices'!C11="",'04 Prices'!C12=""),"",LN('04 Prices'!C12/'04 Prices'!C11)) | D11: =IF(OR($A11="",'04 Prices'!D11="",'04 Prices'!D12=""),"",LN('04 Prices'!D12/'04 Prices'!D11)) | E11: =IF(OR($A11="",'04 Prices'!E11="",'04 Prices'!E12=""),"",LN('04 Prices'!E12/'04 Prices'!E11)) | F11: =IF(OR($A11="",'04 Prices'!F11="",'04 Prices'!F12=""),"",LN('04 Prices'!F12/'04 Prices'!F11)) | G11: =IF(OR($A11="",'04 Prices'!G11="",'04 Prices'!G12=""),"",LN('04 Prices'!G12/'04 Prices'!G11)) | H11: =IF(OR($A11="",'04 Prices'!H11="",'04 Prices'!H12=""),"",LN('04 Prices'!H12/'04 Prices'!H11))
A12: =IF('04 Prices'!A13="","",'04 Prices'!A13) | B12: =IF(OR($A12="",'04 Prices'!B12="",'04 Prices'!B13=""),"",LN('04 Prices'!B13/'04 Prices'!B12)) | C12: =IF(OR($A12="",'04 Prices'!C12="",'04 Prices'!C13=""),"",LN('04 Prices'!C13/'04 Prices'!C12)) | D12: =IF(OR($A12="",'04 Prices'!D12="",'04 Prices'!D13=""),"",LN('04 Prices'!D13/'04 Prices'!D12)) | E12: =IF(OR($A12="",'04 Prices'!E12="",'04 Prices'!E13=""),"",LN('04 Prices'!E13/'04 Prices'!E12)) | F12: =IF(OR($A12="",'04 Prices'!F12="",'04 Prices'!F13=""),"",LN('04 Prices'!F13/'04 Prices'!F12)) | G12: =IF(OR($A12="",'04 Prices'!G12="",'04 Prices'!G13=""),"",LN('04 Prices'!G13/'04 Prices'!G12)) | H12: =IF(OR($A12="",'04 Prices'!H12="",'04 Prices'!H13=""),"",LN('04 Prices'!H13/'04 Prices'!H12))
A13: =IF('04 Prices'!A14="","",'04 Prices'!A14) | B13: =IF(OR($A13="",'04 Prices'!B13="",'04 Prices'!B14=""),"",LN('04 Prices'!B14/'04 Prices'!B13)) | C13: =IF(OR($A13="",'04 Prices'!C13="",'04 Prices'!C14=""),"",LN('04 Prices'!C14/'04 Prices'!C13)) | D13: =IF(OR($A13="",'04 Prices'!D13="",'04 Prices'!D14=""),"",LN('04 Prices'!D14/'04 Prices'!D13)) | E13: =IF(OR($A13="",'04 Prices'!E13="",'04 Prices'!E14=""),"",LN('04 Prices'!E14/'04 Prices'!E13)) | F13: =IF(OR($A13="",'04 Prices'!F13="",'04 Prices'!F14=""),"",LN('04 Prices'!F14/'04 Prices'!F13)) | G13: =IF(OR($A13="",'04 Prices'!G13="",'04 Prices'!G14=""),"",LN('04 Prices'!G14/'04 Prices'!G13)) | H13: =IF(OR($A13="",'04 Prices'!H13="",'04 Prices'!H14=""),"",LN('04 Prices'!H14/'04 Prices'!H13))
A14: =IF('04 Prices'!A15="","",'04 Prices'!A15) | B14: =IF(OR($A14="",'04 Prices'!B14="",'04 Prices'!B15=""),"",LN('04 Prices'!B15/'04 Prices'!B14)) | C14: =IF(OR($A14="",'04 Prices'!C14="",'04 Prices'!C15=""),"",LN('04 Prices'!C15/'04 Prices'!C14)) | D14: =IF(OR($A14="",'04 Prices'!D14="",'04 Prices'!D15=""),"",LN('04 Prices'!D15/'04 Prices'!D14)) | E14: =IF(OR($A14="",'04 Prices'!E14="",'04 Prices'!E15=""),"",LN('04 Prices'!E15/'04 Prices'!E14)) | F14: =IF(OR($A14="",'04 Prices'!F14="",'04 Prices'!F15=""),"",LN('04 Prices'!F15/'04 Prices'!F14)) | G14: =IF(OR($A14="",'04 Prices'!G14="",'04 Prices'!G15=""),"",LN('04 Prices'!G15/'04 Prices'!G14)) | H14: =IF(OR($A14="",'04 Prices'!H14="",'04 Prices'!H15=""),"",LN('04 Prices'!H15/'04 Prices'!H14))
A15: =IF('04 Prices'!A16="","",'04 Prices'!A16) | B15: =IF(OR($A15="",'04 Prices'!B15="",'04 Prices'!B16=""),"",LN('04 Prices'!B16/'04 Prices'!B15)) | C15: =IF(OR($A15="",'04 Prices'!C15="",'04 Prices'!C16=""),"",LN('04 Prices'!C16/'04 Prices'!C15)) | D15: =IF(OR($A15="",'04 Prices'!D15="",'04 Prices'!D16=""),"",LN('04 Prices'!D16/'04 Prices'!D15)) | E15: =IF(OR($A15="",'04 Prices'!E15="",'04 Prices'!E16=""),"",LN('04 Prices'!E16/'04 Prices'!E15)) | F15: =IF(OR($A15="",'04 Prices'!F15="",'04 Prices'!F16=""),"",LN('04 Prices'!F16/'04 Prices'!F15)) | G15: =IF(OR($A15="",'04 Prices'!G15="",'04 Prices'!G16=""),"",LN('04 Prices'!G16/'04 Prices'!G15)) | H15: =IF(OR($A15="",'04 Prices'!H15="",'04 Prices'!H16=""),"",LN('04 Prices'!H16/'04 Prices'!H15))
A16: =IF('04 Prices'!A17="","",'04 Prices'!A17) | B16: =IF(OR($A16="",'04 Prices'!B16="",'04 Prices'!B17=""),"",LN('04 Prices'!B17/'04 Prices'!B16)) | C16: =IF(OR($A16="",'04 Prices'!C16="",'04 Prices'!C17=""),"",LN('04 Prices'!C17/'04 Prices'!C16)) | D16: =IF(OR($A16="",'04 Prices'!D16="",'04 Prices'!D17=""),"",LN('04 Prices'!D17/'04 Prices'!D16)) | E16: =IF(OR($A16="",'04 Prices'!E16="",'04 Prices'!E17=""),"",LN('04 Prices'!E17/'04 Prices'!E16)) | F16: =IF(OR($A16="",'04 Prices'!F16="",'04 Prices'!F17=""),"",LN('04 Prices'!F17/'04 Prices'!F16)) | G16: =IF(OR($A16="",'04 Prices'!G16="",'04 Prices'!G17=""),"",LN('04 Prices'!G17/'04 Prices'!G16)) | H16: =IF(OR($A16="",'04 Prices'!H16="",'04 Prices'!H17=""),"",LN('04 Prices'!H17/'04 Prices'!H16))
... A723: =IF('04 Prices'!A724="","",'04 Prices'!A724) | B723: =IF(OR($A723="",'04 Prices'!B723="",'04 Prices'!B724=""),"",LN('04 Prices'!B724/'04 Prices'!B723)) | C723: =IF(OR($A723="",'04 Prices'!C723="",'04 Prices'!C724=""),"",LN('04 Prices'!C724/'04 Prices'!C723)) | D723: =IF(OR($A723="",'04 Prices'!D723="",'04 Prices'!D724=""),"",LN('04 Prices'!D724/'04 Prices'!D723)) | E723: =IF(OR($A723="",'04 Prices'!E723="",'04 Prices'!E724=""),"",LN('04 Prices'!E724/'04 Prices'!E723)) | F723: =IF(OR($A723="",'04 Prices'!F723="",'04 Prices'!F724=""),"",LN('04 Prices'!F724/'04 Prices'!F723)) | G723: =IF(OR($A723="",'04 Prices'!G723="",'04 Prices'!G724=""),"",LN('04 Prices'!G724/'04 Prices'!G723)) | H723: =IF(OR($A723="",'04 Prices'!H723="",'04 Prices'!H724=""),"",LN('04 Prices'!H724/'04 Prices'!H723))

Sheet 07 Annualised Inputs
A1: Annualised Optimisation Inputs
A2: The two objects Markowitz mean-variance optimisation needs: the vector of annualised expected returns (mu) and the annualised covariance matrix (Sigma). Both are built from LOG returns.
A3: Mirrors: optimization.py -> annualized_inputs(log_return_df)
A5: STEP 1 — ANNUALISED EXPECTED RETURNS mu = mean(daily log return) x 252
A6: Asset | B6: Mean daily log return | C6: Trading days | D6: Annualised expected return (mu)
A7: JPM | B7: =AVERAGE('06 Log Returns'!$B$5:$B$723) | C7: ='02 Config'!$B$12 | D7: =B7*C7
A8: MS | B8: =AVERAGE('06 Log Returns'!$C$5:$C$723) | C8: ='02 Config'!$B$12 | D8: =B8*C8
A9: BAC | B9: =AVERAGE('06 Log Returns'!$D$5:$D$723) | C9: ='02 Config'!$B$12 | D9: =B9*C9
A10: AAPL | B10: =AVERAGE('06 Log Returns'!$E$5:$E$723) | C10: ='02 Config'!$B$12 | D10: =B10*C10
A11: MSFT | B11: =AVERAGE('06 Log Returns'!$F$5:$F$723) | C11: ='02 Config'!$B$12 | D11: =B11*C11
A12: GLD | B12: =AVERAGE('06 Log Returns'!$G$5:$G$723) | C12: ='02 Config'!$B$12 | D12: =B12*C12
A15: STEP 2 — ANNUALISED COVARIANCE MATRIX Sigma = cov(daily log returns) x 252
A16: Asset | B16: JPM | C16: MS | D16: BAC | E16: AAPL | F16: MSFT | G16: GLD
A17: JPM | B17: {=SUMPRODUCT(IF('06 Log Returns'!$B$5:$B$723="",0,'06 Log Returns'!$B$5:$B$723-AVERAGE('06 Log Returns'!$B$5:$B$723)),IF('06 Log Returns'!$B$5:$B$723="",0,'06 Log Returns'!$B$5:$B$723-AVERAGE('06 Log Returns'!$B$5:$B$723)))/(COUNT('06 Log Returns'!$B$5:$B$723)-1)*'02 Config'!$B$12} | C17: {=SUMPRODUCT(IF('06 Log Returns'!$B$5:$B$723="",0,'06 Log Returns'!$B$5:$B$723-AVERAGE('06 Log Returns'!$B$5:$B$723)),IF('06 Log Returns'!$C$5:$C$723="",0,'06 Log Returns'!$C$5:$C$723-AVERAGE('06 Log Returns'!$C$5:$C$723)))/(COUNT('06 Log Returns'!$B$5:$B$723)-1)*'02 Config'!$B$12} | D17: {=SUMPRODUCT(IF('06 Log Returns'!$B$5:$B$723="",0,'06 Log Returns'!$B$5:$B$723-AVERAGE('06 Log Returns'!$B$5:$B$723)),IF('06 Log Returns'!$D$5:$D$723="",0,'06 Log Returns'!$D$5:$D$723-AVERAGE('06 Log Returns'!$D$5:$D$723)))/(COUNT('06 Log Returns'!$B$5:$B$723)-1)*'02 Config'!$B$12} | E17: {=SUMPRODUCT(IF('06 Log Returns'!$B$5:$B$723="",0,'06 Log Returns'!$B$5:$B$723-AVERAGE('06 Log Returns'!$B$5:$B$723)),IF('06 Log Returns'!$E$5:$E$723="",0,'06 Log Returns'!$E$5:$E$723-AVERAGE('06 Log Returns'!$E$5:$E$723)))/(COUNT('06 Log Returns'!$B$5:$B$723)-1)*'02 Config'!$B$12} | F17: {=SUMPRODUCT(IF('06 Log Returns'!$B$5:$B$723="",0,'06 Log Returns'!$B$5:$B$723-AVERAGE('06 Log Returns'!$B$5:$B$723)),IF('06 Log Returns'!$F$5:$F$723="",0,'06 Log Returns'!$F$5:$F$723-AVERAGE('06 Log Returns'!$F$5:$F$723)))/(COUNT('06 Log Returns'!$B$5:$B$723)-1)*'02 Config'!$B$12} | G17: {=SUMPRODUCT(IF('06 Log Returns'!$B$5:$B$723="",0,'06 Log Returns'!$B$5:$B$723-AVERAGE('06 Log Returns'!$B$5:$B$723)),IF('06 Log Returns'!$G$5:$G$723="",0,'06 Log Returns'!$G$5:$G$723-AVERAGE('06 Log Returns'!$G$5:$G$723)))/(COUNT('06 Log Returns'!$B$5:$B$723)-1)*'02 Config'!$B$12}
A18: MS | B18: {=SUMPRODUCT(IF('06 Log Returns'!$C$5:$C$723="",0,'06 Log Returns'!$C$5:$C$723-AVERAGE('06 Log Returns'!$C$5:$C$723)),IF('06 Log Returns'!$B$5:$B$723="",0,'06 Log Returns'!$B$5:$B$723-AVERAGE('06 Log Returns'!$B$5:$B$723)))/(COUNT('06 Log Returns'!$C$5:$C$723)-1)*'02 Config'!$B$12} | C18: {=SUMPRODUCT(IF('06 Log Returns'!$C$5:$C$723="",0,'06 Log Returns'!$C$5:$C$723-AVERAGE('06 Log Returns'!$C$5:$C$723)),IF('06 Log Returns'!$C$5:$C$723="",0,'06 Log Returns'!$C$5:$C$723-AVERAGE('06 Log Returns'!$C$5:$C$723)))/(COUNT('06 Log Returns'!$C$5:$C$723)-1)*'02 Config'!$B$12} | D18: {=SUMPRODUCT(IF('06 Log Returns'!$C$5:$C$723="",0,'06 Log Returns'!$C$5:$C$723-AVERAGE('06 Log Returns'!$C$5:$C$723)),IF('06 Log Returns'!$D$5:$D$723="",0,'06 Log Returns'!$D$5:$D$723-AVERAGE('06 Log Returns'!$D$5:$D$723)))/(COUNT('06 Log Returns'!$C$5:$C$723)-1)*'02 Config'!$B$12} | E18: {=SUMPRODUCT(IF('06 Log Returns'!$C$5:$C$723="",0,'06 Log Returns'!$C$5:$C$723-AVERAGE('06 Log Returns'!$C$5:$C$723)),IF('06 Log Returns'!$E$5:$E$723="",0,'06 Log Returns'!$E$5:$E$723-AVERAGE('06 Log Returns'!$E$5:$E$723)))/(COUNT('06 Log Returns'!$C$5:$C$723)-1)*'02 Config'!$B$12} | F18: {=SUMPRODUCT(IF('06 Log Returns'!$C$5:$C$723="",0,'06 Log Returns'!$C$5:$C$723-AVERAGE('06 Log Returns'!$C$5:$C$723)),IF('06 Log Returns'!$F$5:$F$723="",0,'06 Log Returns'!$F$5:$F$723-AVERAGE('06 Log Returns'!$F$5:$F$723)))/(COUNT('06 Log Returns'!$C$5:$C$723)-1)*'02 Config'!$B$12} | G18: {=SUMPRODUCT(IF('06 Log Returns'!$C$5:$C$723="",0,'06 Log Returns'!$C$5:$C$723-AVERAGE('06 Log Returns'!$C$5:$C$723)),IF('06 Log Returns'!$G$5:$G$723="",0,'06 Log Returns'!$G$5:$G$723-AVERAGE('06 Log Returns'!$G$5:$G$723)))/(COUNT('06 Log Returns'!$C$5:$C$723)-1)*'02 Config'!$B$12}
A19: BAC | B19: {=SUMPRODUCT(IF('06 Log Returns'!$D$5:$D$723="",0,'06 Log Returns'!$D$5:$D$723-AVERAGE('06 Log Returns'!$D$5:$D$723)),IF('06 Log Returns'!$B$5:$B$723="",0,'06 Log Returns'!$B$5:$B$723-AVERAGE('06 Log Returns'!$B$5:$B$723)))/(COUNT('06 Log Returns'!$D$5:$D$723)-1)*'02 Config'!$B$12} | C19: {=SUMPRODUCT(IF('06 Log Returns'!$D$5:$D$723="",0,'06 Log Returns'!$D$5:$D$723-AVERAGE('06 Log Returns'!$D$5:$D$723)),IF('06 Log Returns'!$C$5:$C$723="",0,'06 Log Returns'!$C$5:$C$723-AVERAGE('06 Log Returns'!$C$5:$C$723)))/(COUNT('06 Log Returns'!$D$5:$D$723)-1)*'02 Config'!$B$12} | D19: {=SUMPRODUCT(IF('06 Log Returns'!$D$5:$D$723="",0,'06 Log Returns'!$D$5:$D$723-AVERAGE('06 Log Returns'!$D$5:$D$723)),IF('06 Log Returns'!$D$5:$D$723="",0,'06 Log Returns'!$D$5:$D$723-AVERAGE('06 Log Returns'!$D$5:$D$723)))/(COUNT('06 Log Returns'!$D$5:$D$723)-1)*'02 Config'!$B$12} | E19: {=SUMPRODUCT(IF('06 Log Returns'!$D$5:$D$723="",0,'06 Log Returns'!$D$5:$D$723-AVERAGE('06 Log Returns'!$D$5:$D$723)),IF('06 Log Returns'!$E$5:$E$723="",0,'06 Log Returns'!$E$5:$E$723-AVERAGE('06 Log Returns'!$E$5:$E$723)))/(COUNT('06 Log Returns'!$D$5:$D$723)-1)*'02 Config'!$B$12} | F19: {=SUMPRODUCT(IF('06 Log Returns'!$D$5:$D$723="",0,'06 Log Returns'!$D$5:$D$723-AVERAGE('06 Log Returns'!$D$5:$D$723)),IF('06 Log Returns'!$F$5:$F$723="",0,'06 Log Returns'!$F$5:$F$723-AVERAGE('06 Log Returns'!$F$5:$F$723)))/(COUNT('06 Log Returns'!$D$5:$D$723)-1)*'02 Config'!$B$12} | G19: {=SUMPRODUCT(IF('06 Log Returns'!$D$5:$D$723="",0,'06 Log Returns'!$D$5:$D$723-AVERAGE('06 Log Returns'!$D$5:$D$723)),IF('06 Log Returns'!$G$5:$G$723="",0,'06 Log Returns'!$G$5:$G$723-AVERAGE('06 Log Returns'!$G$5:$G$723)))/(COUNT('06 Log Returns'!$D$5:$D$723)-1)*'02 Config'!$B$12}
A20: AAPL | B20: {=SUMPRODUCT(IF('06 Log Returns'!$E$5:$E$723="",0,'06 Log Returns'!$E$5:$E$723-AVERAGE('06 Log Returns'!$E$5:$E$723)),IF('06 Log Returns'!$B$5:$B$723="",0,'06 Log Returns'!$B$5:$B$723-AVERAGE('06 Log Returns'!$B$5:$B$723)))/(COUNT('06 Log Returns'!$E$5:$E$723)-1)*'02 Config'!$B$12} | C20: {=SUMPRODUCT(IF('06 Log Returns'!$E$5:$E$723="",0,'06 Log Returns'!$E$5:$E$723-AVERAGE('06 Log Returns'!$E$5:$E$723)),IF('06 Log Returns'!$C$5:$C$723="",0,'06 Log Returns'!$C$5:$C$723-AVERAGE('06 Log Returns'!$C$5:$C$723)))/(COUNT('06 Log Returns'!$E$5:$E$723)-1)*'02 Config'!$B$12} | D20: {=SUMPRODUCT(IF('06 Log Returns'!$E$5:$E$723="",0,'06 Log Returns'!$E$5:$E$723-AVERAGE('06 Log Returns'!$E$5:$E$723)),IF('06 Log Returns'!$D$5:$D$723="",0,'06 Log Returns'!$D$5:$D$723-AVERAGE('06 Log Returns'!$D$5:$D$723)))/(COUNT('06 Log Returns'!$E$5:$E$723)-1)*'02 Config'!$B$12} | E20: {=SUMPRODUCT(IF('06 Log Returns'!$E$5:$E$723="",0,'06 Log Returns'!$E$5:$E$723-AVERAGE('06 Log Returns'!$E$5:$E$723)),IF('06 Log Returns'!$E$5:$E$723="",0,'06 Log Returns'!$E$5:$E$723-AVERAGE('06 Log Returns'!$E$5:$E$723)))/(COUNT('06 Log Returns'!$E$5:$E$723)-1)*'02 Config'!$B$12} | F20: {=SUMPRODUCT(IF('06 Log Returns'!$E$5:$E$723="",0,'06 Log Returns'!$E$5:$E$723-AVERAGE('06 Log Returns'!$E$5:$E$723)),IF('06 Log Returns'!$F$5:$F$723="",0,'06 Log Returns'!$F$5:$F$723-AVERAGE('06 Log Returns'!$F$5:$F$723)))/(COUNT('06 Log Returns'!$E$5:$E$723)-1)*'02 Config'!$B$12} | G20: {=SUMPRODUCT(IF('06 Log Returns'!$E$5:$E$723="",0,'06 Log Returns'!$E$5:$E$723-AVERAGE('06 Log Returns'!$E$5:$E$723)),IF('06 Log Returns'!$G$5:$G$723="",0,'06 Log Returns'!$G$5:$G$723-AVERAGE('06 Log Returns'!$G$5:$G$723)))/(COUNT('06 Log Returns'!$E$5:$E$723)-1)*'02 Config'!$B$12}
A21: MSFT | B21: {=SUMPRODUCT(IF('06 Log Returns'!$F$5:$F$723="",0,'06 Log Returns'!$F$5:$F$723-AVERAGE('06 Log Returns'!$F$5:$F$723)),IF('06 Log Returns'!$B$5:$B$723="",0,'06 Log Returns'!$B$5:$B$723-AVERAGE('06 Log Returns'!$B$5:$B$723)))/(COUNT('06 Log Returns'!$F$5:$F$723)-1)*'02 Config'!$B$12} | C21: {=SUMPRODUCT(IF('06 Log Returns'!$F$5:$F$723="",0,'06 Log Returns'!$F$5:$F$723-AVERAGE('06 Log Returns'!$F$5:$F$723)),IF('06 Log Returns'!$C$5:$C$723="",0,'06 Log Returns'!$C$5:$C$723-AVERAGE('06 Log Returns'!$C$5:$C$723)))/(COUNT('06 Log Returns'!$F$5:$F$723)-1)*'02 Config'!$B$12} | D21: {=SUMPRODUCT(IF('06 Log Returns'!$F$5:$F$723="",0,'06 Log Returns'!$F$5:$F$723-AVERAGE('06 Log Returns'!$F$5:$F$723)),IF('06 Log Returns'!$D$5:$D$723="",0,'06 Log Returns'!$D$5:$D$723-AVERAGE('06 Log Returns'!$D$5:$D$723)))/(COUNT('06 Log Returns'!$F$5:$F$723)-1)*'02 Config'!$B$12} | E21: {=SUMPRODUCT(IF('06 Log Returns'!$F$5:$F$723="",0,'06 Log Returns'!$F$5:$F$723-AVERAGE('06 Log Returns'!$F$5:$F$723)),IF('06 Log Returns'!$E$5:$E$723="",0,'06 Log Returns'!$E$5:$E$723-AVERAGE('06 Log Returns'!$E$5:$E$723)))/(COUNT('06 Log Returns'!$F$5:$F$723)-1)*'02 Config'!$B$12} | F21: {=SUMPRODUCT(IF('06 Log Returns'!$F$5:$F$723="",0,'06 Log Returns'!$F$5:$F$723-AVERAGE('06 Log Returns'!$F$5:$F$723)),IF('06 Log Returns'!$F$5:$F$723="",0,'06 Log Returns'!$F$5:$F$723-AVERAGE('06 Log Returns'!$F$5:$F$723)))/(COUNT('06 Log Returns'!$F$5:$F$723)-1)*'02 Config'!$B$12} | G21: {=SUMPRODUCT(IF('06 Log Returns'!$F$5:$F$723="",0,'06 Log Returns'!$F$5:$F$723-AVERAGE('06 Log Returns'!$F$5:$F$723)),IF('06 Log Returns'!$G$5:$G$723="",0,'06 Log Returns'!$G$5:$G$723-AVERAGE('06 Log Returns'!$G$5:$G$723)))/(COUNT('06 Log Returns'!$F$5:$F$723)-1)*'02 Config'!$B$12}
A22: GLD | B22: {=SUMPRODUCT(IF('06 Log Returns'!$G$5:$G$723="",0,'06 Log Returns'!$G$5:$G$723-AVERAGE('06 Log Returns'!$G$5:$G$723)),IF('06 Log Returns'!$B$5:$B$723="",0,'06 Log Returns'!$B$5:$B$723-AVERAGE('06 Log Returns'!$B$5:$B$723)))/(COUNT('06 Log Returns'!$G$5:$G$723)-1)*'02 Config'!$B$12} | C22: {=SUMPRODUCT(IF('06 Log Returns'!$G$5:$G$723="",0,'06 Log Returns'!$G$5:$G$723-AVERAGE('06 Log Returns'!$G$5:$G$723)),IF('06 Log Returns'!$C$5:$C$723="",0,'06 Log Returns'!$C$5:$C$723-AVERAGE('06 Log Returns'!$C$5:$C$723)))/(COUNT('06 Log Returns'!$G$5:$G$723)-1)*'02 Config'!$B$12} | D22: {=SUMPRODUCT(IF('06 Log Returns'!$G$5:$G$723="",0,'06 Log Returns'!$G$5:$G$723-AVERAGE('06 Log Returns'!$G$5:$G$723)),IF('06 Log Returns'!$D$5:$D$723="",0,'06 Log Returns'!$D$5:$D$723-AVERAGE('06 Log Returns'!$D$5:$D$723)))/(COUNT('06 Log Returns'!$G$5:$G$723)-1)*'02 Config'!$B$12} | E22: {=SUMPRODUCT(IF('06 Log Returns'!$G$5:$G$723="",0,'06 Log Returns'!$G$5:$G$723-AVERAGE('06 Log Returns'!$G$5:$G$723)),IF('06 Log Returns'!$E$5:$E$723="",0,'06 Log Returns'!$E$5:$E$723-AVERAGE('06 Log Returns'!$E$5:$E$723)))/(COUNT('06 Log Returns'!$G$5:$G$723)-1)*'02 Config'!$B$12} | F22: {=SUMPRODUCT(IF('06 Log Returns'!$G$5:$G$723="",0,'06 Log Returns'!$G$5:$G$723-AVERAGE('06 Log Returns'!$G$5:$G$723)),IF('06 Log Returns'!$F$5:$F$723="",0,'06 Log Returns'!$F$5:$F$723-AVERAGE('06 Log Returns'!$F$5:$F$723)))/(COUNT('06 Log Returns'!$G$5:$G$723)-1)*'02 Config'!$B$12} | G22: {=SUMPRODUCT(IF('06 Log Returns'!$G$5:$G$723="",0,'06 Log Returns'!$G$5:$G$723-AVERAGE('06 Log Returns'!$G$5:$G$723)),IF('06 Log Returns'!$G$5:$G$723="",0,'06 Log Returns'!$G$5:$G$723-AVERAGE('06 Log Returns'!$G$5:$G$723)))/(COUNT('06 Log Returns'!$G$5:$G$723)-1)*'02 Config'!$B$12}
A25: STEP 3 — CORRELATION MATRIX (diagnostic — not used by the optimiser)
A26: Asset | B26: JPM | C26: MS | D26: BAC | E26: AAPL | F26: MSFT | G26: GLD
A27: JPM | B27: =$B$17/(SQRT($B$17)*SQRT($B$17)) | C27: =$C$17/(SQRT($B$17)*SQRT($C$18)) | D27: =$D$17/(SQRT($B$17)*SQRT($D$19)) | E27: =$E$17/(SQRT($B$17)*SQRT($E$20)) | F27: =$F$17/(SQRT($B$17)*SQRT($F$21)) | G27: =$G$17/(SQRT($B$17)*SQRT($G$22))
A28: MS | B28: =$B$18/(SQRT($C$18)*SQRT($B$17)) | C28: =$C$18/(SQRT($C$18)*SQRT($C$18)) | D28: =$D$18/(SQRT($C$18)*SQRT($D$19)) | E28: =$E$18/(SQRT($C$18)*SQRT($E$20)) | F28: =$F$18/(SQRT($C$18)*SQRT($F$21)) | G28: =$G$18/(SQRT($C$18)*SQRT($G$22))
A29: BAC | B29: =$B$19/(SQRT($D$19)*SQRT($B$17)) | C29: =$C$19/(SQRT($D$19)*SQRT($C$18)) | D29: =$D$19/(SQRT($D$19)*SQRT($D$19)) | E29: =$E$19/(SQRT($D$19)*SQRT($E$20)) | F29: =$F$19/(SQRT($D$19)*SQRT($F$21)) | G29: =$G$19/(SQRT($D$19)*SQRT($G$22))
A30: AAPL | B30: =$B$20/(SQRT($E$20)*SQRT($B$17)) | C30: =$C$20/(SQRT($E$20)*SQRT($C$18)) | D30: =$D$20/(SQRT($E$20)*SQRT($D$19)) | E30: =$E$20/(SQRT($E$20)*SQRT($E$20)) | F30: =$F$20/(SQRT($E$20)*SQRT($F$21)) | G30: =$G$20/(SQRT($E$20)*SQRT($G$22))
A31: MSFT | B31: =$B$21/(SQRT($F$21)*SQRT($B$17)) | C31: =$C$21/(SQRT($F$21)*SQRT($C$18)) | D31: =$D$21/(SQRT($F$21)*SQRT($D$19)) | E31: =$E$21/(SQRT($F$21)*SQRT($E$20)) | F31: =$F$21/(SQRT($F$21)*SQRT($F$21)) | G31: =$G$21/(SQRT($F$21)*SQRT($G$22))
A32: GLD | B32: =$B$22/(SQRT($G$22)*SQRT($B$17)) | C32: =$C$22/(SQRT($G$22)*SQRT($C$18)) | D32: =$D$22/(SQRT($G$22)*SQRT($D$19)) | E32: =$E$22/(SQRT($G$22)*SQRT($E$20)) | F32: =$F$22/(SQRT($G$22)*SQRT($F$21)) | G32: =$G$22/(SQRT($G$22)*SQRT($G$22))

Sheet 08 Optimisation
A1: Markowitz Mean-Variance Optimisation — Closed Form
A2: Solved with matrix algebra (MINVERSE / MMULT) rather than a numerical optimiser, so every weight is a live formula. This is the UNCONSTRAINED solution: weights may go negative (short positions).
A3: Mirrors: optimization.py -> PortfolioMath, minimum_volatility_portfolio(), maximum_sharpe_portfolio(), efficient_frontier()
A4: IMPORTANT — how this differs from the Python project: optimization.py constrains weights to [0, 1] (long-only) and solves numerically with SciPy's SLSQP. A bounded problem like that has no closed form. The matrix solution below is the analytically exact answer to the SAME objective WITHOUT the bounds, so where a short position would improve the portfolio these weights will differ from the Python output.
A6: STEP 1 — INVERT THE COVARIANCE MATRIX (Sigma^-1)
A7: Asset | B7: JPM | C7: MS | D7: BAC | E7: AAPL | F7: MSFT | G7: GLD
A8: JPM | B8: {=MINVERSE('07 Annualised Inputs'!$B$17:$G$22)}
A9: MS
A10: BAC
A11: AAPL
A12: MSFT
A13: GLD
A16: STEP 2 — THE THREE BUILDING-BLOCK VECTORS
A17: Asset | B17: Sigma^-1 . 1 | C17: Sigma^-1 . mu | D17: Sigma^-1 . (mu - rf.1)
A18: JPM | B18: =SUM(B8:G8) | C18: =SUM(MMULT(B8:G8,'07 Annualised Inputs'!$D$7:$D$12)) | D18: =C18-'02 Config'!$B$10*B18
A19: MS | B19: =SUM(B9:G9) | C19: =SUM(MMULT(B9:G9,'07 Annualised Inputs'!$D$7:$D$12)) | D19: =C19-'02 Config'!$B$10*B19
A20: BAC | B20: =SUM(B10:G10) | C20: =SUM(MMULT(B10:G10,'07 Annualised Inputs'!$D$7:$D$12)) | D20: =C20-'02 Config'!$B$10*B20
A21: AAPL | B21: =SUM(B11:G11) | C21: =SUM(MMULT(B11:G11,'07 Annualised Inputs'!$D$7:$D$12)) | D21: =C21-'02 Config'!$B$10*B21
A22: MSFT | B22: =SUM(B12:G12) | C22: =SUM(MMULT(B12:G12,'07 Annualised Inputs'!$D$7:$D$12)) | D22: =C22-'02 Config'!$B$10*B22
A23: GLD | B23: =SUM(B13:G13) | C23: =SUM(MMULT(B13:G13,'07 Annualised Inputs'!$D$7:$D$12)) | D23: =C23-'02 Config'!$B$10*B23
A26: STEP 3 — THE FOUR SCALAR CONSTANTS OF THE FRONTIER
A27: Constant | B27: Value | C27: Definition | D27: Meaning
A28: A | B28: =SUM(B18:B23) | C28: 1' Sigma^-1 1 | D28: Total 'precision' available. 1/A is the variance of the global minimum-variance portfolio.
A29: B | B29: =SUM(C18:C23) | C29: 1' Sigma^-1 mu | D29: Links the return vector to the weighting scheme. B/A is the min-variance portfolio's expected return.
A30: C | B30: =SUMPRODUCT('07 Annualised Inputs'!$D$7:$D$12,C18:C23) | C30: mu' Sigma^-1 mu | D30: Risk-adjusted magnitude of the expected-return vector.
A31: D | B31: =B28*B30-B29^2 | C31: A.C - B^2 | D31: The frontier's curvature. Positive whenever Sigma is well behaved; it is the denominator of the frontier equation.
A33: STEP 4 — MINIMUM VARIANCE PORTFOLIO w = (Sigma^-1 . 1) / A
A34: These are the weights the rest of the workbook uses as THE portfolio, exactly as main.py does.
A35: Asset | B35: Weight
A36: JPM | B36: =B18/$B$28
A37: MS | B37: =B19/$B$28
A38: BAC | B38: =B20/$B$28
A39: AAPL | B39: =B21/$B$28
A40: MSFT | B40: =B22/$B$28
A41: GLD | B41: =B23/$B$28
A42: Sum of weights (must equal 100%) | B42: =SUM(B36:B41)
A43: Expected annual return | B43: =SUMPRODUCT('07 Annualised Inputs'!$D$7:$D$12,'08 Optimisation'!$B$36:$B$41)
A44: Annual volatility (risk) | B44: =SQRT(SUMPRODUCT(MMULT(TRANSPOSE('08 Optimisation'!$B$36:$B$41),'07 Annualised Inputs'!$B$17:$G$22),TRANSPOSE('08 Optimisation'!$B$36:$B$41)))
A45: Sharpe ratio | B45: =(B43-'02 Config'!$B$10)/B44
A48: STEP 5 — MAXIMUM SHARPE (TANGENCY) PORTFOLIO w = Sigma^-1 (mu - rf.1) / 1'Sigma^-1 (mu - rf.1)
...

Sheet 09 Monte Carlo
A1: Monte Carlo Simulation of the Feasible Set
A2: 1,000 randomly weighted long-only portfolios. Plotted as a cloud, they fill in the region of risk/return space a portfolio can actually reach — the efficient frontier is its upper-left edge.
A3: Mirrors: optimization.py -> monte_carlo_portfolios(pm, n_portfolios, seed)
A4: The six blue columns are the raw uniform random draws produced by numpy's default_rng(seed=42) — the same generator and seed as config.py — so these rows reproduce the first rows of the Python simulation exactly. They are pasted as fixed values rather than RAND(), which would reshuffle the cloud on every keystroke and make the charts flicker. Everything to the right of them is live formula.
A5: # | B5: draw JPM | C5: draw MS | D5: draw BAC | E5: draw AAPL | F5: draw MSFT | G5: draw GLD | H5: Sum of draws | I5: w JPM | J5: w MS | K5: w BAC | L5: w AAPL | M5: w MSFT | N5: w GLD | O5: Return | P5: Volatility | Q5: Sharpe | S5: SIMULATION SUMMARY
A6: 1 | B6: 0.77395605 | C6: 0.43887844 | D6: 0.85859792 | E6: 0.69736803 | F6: 0.094177348 | G6: 0.97562235 | H6: =SUM(B6:G6) | I6: =B6/$H6 | J6: =C6/$H6 | K6: =D6/$H6 | L6: =E6/$H6 | M6: =F6/$H6 | N6: =G6/$H6 | O6: =SUM(MMULT(I6:N6,'07 Annualised Inputs'!$D$7:$D$12)) | P6: =SQRT(SUMPRODUCT(MMULT(I6:N6,'07 Annualised Inputs'!$B$17:$G$22),I6:N6)) | Q6: =(O6-'02 Config'!$B$10)/P6 | S6: Lowest simulated return | V6: =MIN($O$6:$O$1005)
A7: 2 | B7: 0.7611397 | C7: 0.78606431 | D7: 0.12811363 | E7: 0.45038594 | F7: 0.37079802 | G7: 0.92676499 | H7: =SUM(B7:G7) | I7: =B7/$H7 | J7: =C7/$H7 | K7: =D7/$H7 | L7: =E7/$H7 | M7: =F7/$H7 | N7: =G7/$H7 | O7: =SUM(MMULT(I7:N7,'07 Annualised Inputs'!$D$7:$D$12)) | P7: =SQRT(SUMPRODUCT(MMULT(I7:N7,'07 Annualised Inputs'!$B$17:$G$22),I7:N7)) | Q7: =(O7-'02 Config'!$B$10)/P7 | S7: Highest simulated return | V7: =MAX($O$6:$O$1005)
A8: 3 | B8: 0.64386512 | C8: 0.82276161 | D8: 0.4434142 | E8: 0.22723872 | F8: 0.55458479 | G8: 0.063817256 | H8: =SUM(B8:G8) | I8: =B8/$H8 | J8: =C8/$H8 | K8: =D8/$H8 | L8: =E8/$H8 | M8: =F8/$H8 | N8: =G8/$H8 | O8: =SUM(MMULT(I8:N8,'07 Annualised Inputs'!$D$7:$D$12)) | P8: =SQRT(SUMPRODUCT(MMULT(I8:N8,'07 Annualised Inputs'!$B$17:$G$22),I8:N8)) | Q8: =(O8-'02 Config'!$B$10)/P8 | S8: Lowest simulated volatility | V8: =MIN($P$6:$P$1005)
